Workbook

Sheet Feuil1
A1: matricule | B1: ordre | C1: nom | D1: prenom | E1: date_nais | F1: sexe | G1: etat_civil | H1: type_piece | I1: num_piece | J1: adresse | K1: ville | L1: code_postal | M1: gsm | N1: email | O1: rib
A2: 100 | B2: 0 | C2: =IF(B2=0,VLOOKUP(A2,Feuil2!$A$2:$M$1241,2,FALSE)," ") -> JARRAR | D2: =IF(B2=0,VLOOKUP(A2,Feuil2!$A$2:$M$1241,3,FALSE)," ") -> JALEL BEN ALI | E2: =IF(B2=0,VLOOKUP(A2,Feuil2!$A$2:$M$1241,6,FALSE)," ") -> 23125 | F2: =IF(B2=0,VLOOKUP(A2,Feuil2!$A$2:$M$1241,12,FALSE)," ") -> H | G2: =IF(B2=0,VLOOKUP(A2,Feuil2!$A$2:$M$1241,11,FALSE)," ") -> M | H2: C | I2: =IF(B2=0,VLOOKUP(A2,Feuil2!$A$2:$M$1241,7,FALSE)," ") -> 2961061 | J2: =IF(B2=0,VLOOKUP(A2,Feuil2!$A$2:$M$1241,9,FALSE)," ") -> 55 Route de Sfax | K2: =IF(B2=0,VLOOKUP(A2,Feuil2!$A$2:$M$1241,10,FALSE)," ") -> Msaken 4070 | L2: 4070 | M2: 98793700 | O2: =IF(B2=0,VLOOKUP(A2,Feuil2!$A$2:$M$1241,13,FALSE)," ") -> 11020002050700878842
A3: 100 | B3: 1 | C3: MLAYEH | D3: THOURAYA | E3: 26310 | F3: F | G3: M | H3: C | I3: =IF(B3=0,VLOOKUP(A3,Feuil2!$A$2:$M$1241,7,FALSE)," ") | J3: =IF(B3=0,VLOOKUP(A3,Feuil2!$A$2:$M$1241,9,FALSE)," ") | K3: =IF(B3=0,VLOOKUP(A3,Feuil2!$A$2:$M$1241,10,FALSE)," ") | O3: =IF(B3=0,VLOOKUP(A3,Feuil2!$A$2:$M$1241,13,FALSE)," ")
A4: 100 | B4: 2 | C4: JARRAR | D4: FOUED | E4: 35702 | F4: H | G4: =IF(B4=0,VLOOKUP(A4,Feuil2!$A$2:$M$1241,11,FALSE)," ") | H4: C | I4: =IF(B4=0,VLOOKUP(A4,Feuil2!$A$2:$M$1241,7,FALSE)," ") | J4: =IF(B4=0,VLOOKUP(A4,Feuil2!$A$2:$M$1241,9,FALSE)," ") | K4: =IF(B4=0,VLOOKUP(A4,Feuil2!$A$2:$M$1241,10,FALSE)," ") | O4: =IF(B4=0,VLOOKUP(A4,Feuil2!$A$2:$M$1241,13,FALSE)," ")
A5: 100 | B5: 3 | C5: JARRAR | D5: FATEN | E5: 36388 | F5: F | G5: =IF(B5=0,VLOOKUP(A5,Feuil2!$A$2:$M$1241,11,FALSE)," ") | H5: C | I5: =IF(B5=0,VLOOKUP(A5,Feuil2!$A$2:$M$1241,7,FALSE)," ") | J5: =IF(B5=0,VLOOKUP(A5,Feuil2!$A$2:$M$1241,9,FALSE)," ") | K5: =IF(B5=0,VLOOKUP(A5,Feuil2!$A$2:$M$1241,10,FALSE)," ") | O5: =IF(B5=0,VLOOKUP(A5,Feuil2!$A$2:$M$1241,13,FALSE)," ")
A6: 100 | B6: 4 | C6: JARRAR | D6: IBRAHIM | E6: 38394 | F6: H | G6: =IF(B6=0,VLOOKUP(A6,Feuil2!$A$2:$M$1241,11,FALSE)," ") | H6: C | I6: =IF(B6=0,VLOOKUP(A6,Feuil2!$A$2:$M$1241,7,FALSE)," ") | J6: =IF(B6=0,VLOOKUP(A6,Feuil2!$A$2:$M$1241,9,FALSE)," ") | K6: =IF(B6=0,VLOOKUP(A6,Feuil2!$A$2:$M$1241,10,FALSE)," ") | O6: =IF(B6=0,VLOOKUP(A6,Feuil2!$A$2:$M$1241,13,FALSE)," ")
A7: 100 | B7: 5 | C7: JARRAR | D7: SOUFIEN | E7: 38909 | F7: H | G7: =IF(B7=0,VLOOKUP(A7,Feuil2!$A$2:$M$1241,11,FALSE)," ") | H7: C | I7: =IF(B7=0,VLOOKUP(A7,Feuil2!$A$2:$M$1241,7,FALSE)," ") | J7: =IF(B7=0,VLOOKUP(A7,Feuil2!$A$2:$M$1241,9,FALSE)," ") | K7: =IF(B7=0,VLOOKUP(A7,Feuil2!$A$2:$M$1241,10,FALSE)," ") | O7: =IF(B7=0,VLOOKUP(A7,Feuil2!$A$2:$M$1241,13,FALSE)," ")
A8: 134 | B8: 0 | C8: =IF(B8=0,VLOOKUP(A8,Feuil2!$A$2:$M$1241,2,FALSE)," ") -> JARRAR | D8: =IF(B8=0,VLOOKUP(A8,Feuil2!$A$2:$M$1241,3,FALSE)," ") -> JALEL | E8: =IF(B8=0,VLOOKUP(A8,Feuil2!$A$2:$M$1241,6,FALSE)," ") -> 22389 | F8: =IF(B8=0,VLOOKUP(A8,Feuil2!$A$2:$M$1241,12,FALSE)," ") -> H | G8: V | H8: C | I8: =IF(B8=0,VLOOKUP(A8,Feuil2!$A$2:$M$1241,7,FALSE)," ") -> 2844703 | J8: =IF(B8=0,VLOOKUP(A8,Feuil2!$A$2:$M$1241,9,FALSE)," ") -> 52, Rue HÃ©di Khefacha CitÃ© Erriadh | K8: =IF(B8=0,VLOOKUP(A8,Feuil2!$A$2:$M$1241,10,FALSE)," ") -> Sousse | M8: 98793545 | O8: 08507000262000577307
A9: 134 | B9: 1 | C9: JARRAR | D9: ZIED | E9: 34599 | F9: H | G9: =IF(B9=0,VLOOKUP(A9,Feuil2!$A$2:$M$1241,11,FALSE)," ") | H9: C | I9: =IF(B9=0,VLOOKUP(A9,Feuil2!$A$2:$M$1241,7,FALSE)," ") | J9: =IF(B9=0,VLOOKUP(A9,Feuil2!$A$2:$M$1241,9,FALSE)," ") | K9: =IF(B9=0,VLOOKUP(A9,Feuil2!$A$2:$M$1241,10,FALSE)," ")
A10: 185 | B10: 0 | C10: =IF(B10=0,VLOOKUP(A10,Feuil2!$A$2:$M$1241,2,FALSE)," ") -> MAHJOUB NOUIR | D10: =IF(B10=0,VLOOKUP(A10,Feuil2!$A$2:$M$1241,3,FALSE)," ") -> MONCEF | E10: =IF(B10=0,VLOOKUP(A10,Feuil2!$A$2:$M$1241,6,FALSE)," ") -> 23612 | F10: =IF(B10=0,VLOOKUP(A10,Feuil2!$A$2:$M$1241,12,FALSE)," ") -> H | G10: =IF(B10=0,VLOOKUP(A10,Feuil2!$A$2:$M$1241,11,FALSE)," ") -> M | H10: C | I10: =IF(B10=0,VLOOKUP(A10,Feuil2!$A$2:$M$1241,7,FALSE)," ") -> 2959720 | J10: =IF(B10=0,VLOOKUP(A10,Feuil2!$A$2:$M$1241,9,FALSE)," ") -> 37 rue Ibn Rochd | K10: =IF(B10=0,VLOOKUP(A10,Feuil2!$A$2:$M$1241,10,FALSE)," ") -> Msaken 4070 | L10: 4070 | M10: 26836854 | O10: =IF(B10=0,VLOOKUP(A10,Feuil2!$A$2:$M$1241,13,FALSE)," ") -> 03508056010100247580
A11: 185 | B11: 1 | C11: ABBASS | D11: RADHIA | E11: 26829 | F11: F | G11: M | H11: C | I11: =IF(B11=0,VLOOKUP(A11,Feuil2!$A$2:$M$1241,7,FALSE)," ") | J11: =IF(B11=0,VLOOKUP(A11,Feuil2!$A$2:$M$1241,9,FALSE)," ") | K11: =IF(B11=0,VLOOKUP(A11,Feuil2!$A$2:$M$1241,10,FALSE)," ") | O11: =IF(B11=0,VLOOKUP(A11,Feuil2!$A$2:$M$1241,13,FALSE)," ")
A12: 185 | B12: 2 | C12: MAHJOUB NOUIR | D12: AYOUB | E12: 37775 | F12: H | G12: =IF(B12=0,VLOOKUP(A12,Feuil2!$A$2:$M$1241,11,FALSE)," ") | H12: C | I12: =IF(B12=0,VLOOKUP(A12,Feuil2!$A$2:$M$1241,7,FALSE)," ") | J12: =IF(B12=0,VLOOKUP(A12,Feuil2!$A$2:$M$1241,9,FALSE)," ") | K12: =IF(B12=0,VLOOKUP(A12,Feuil2!$A$2:$M$1241,10,FALSE)," ") | O12: =IF(B12=0,VLOOKUP(A12,Feuil2!$A$2:$M$1241,13,FALSE)," ")
A13: 212 | B13: 0 | C13: =IF(B13=0,VLOOKUP(A13,Feuil2!$A$2:$M$1241,2,FALSE)," ") -> BOUHLEL | D13: =IF(B13=0,VLOOKUP(A13,Feuil2!$A$2:$M$1241,3,FALSE)," ") -> BECHIR | E13: =IF(B13=0,VLOOKUP(A13,Feuil2!$A$2:$M$1241,6,FALSE)," ") -> 23594 | F13: =IF(B13=0,VLOOKUP(A13,Feuil2!$A$2:$M$1241,12,FALSE)," ") -> H | G13: =IF(B13=0,VLOOKUP(A13,Feuil2!$A$2:$M$1241,11,FALSE)," ") -> M | H13: C | I13: =IF(B13=0,VLOOKUP(A13,Feuil2!$A$2:$M$1241,7,FALSE)," ") -> 2954309 | J13: =IF(B13=0,VLOOKUP(A13,Feuil2!$A$2:$M$1241,9,FALSE)," ") -> Rue de Iran | K13: =IF(B13=0,VLOOKUP(A13,Feuil2!$A$2:$M$1241,10,FALSE)," ") -> Msaken 4070 | L13: 4070 | M13: 98793620 | O13: =IF(B13=0,VLOOKUP(A13,Feuil2!$A$2:$M$1241,13,FALSE)," ") -> 08507000262001609096
A14: 212 | B14: 1 | C14: GUEZGUEZ | D14: SAMIA | E14: 26636 | F14: F | G14: M | H14: C | I14: =IF(B14=0,VLOOKUP(A14,Feuil2!$A$2:$M$1241,7,FALSE)," ") | J14: =IF(B14=0,VLOOKUP(A14,Feuil2!$A$2:$M$1241,9,FALSE)," ") | K14: =IF(B14=0,VLOOKUP(A14,Feuil2!$A$2:$M$1241,10,FALSE)," ") | O14: =IF(B14=0,VLOOKUP(A14,Feuil2!$A$2:$M$1241,13,FALSE)," ")
A15: 212 | B15: 2 | C15: BOUHLEL | D15: YOUSSEF | E15: 40328 | F15: F | G15: =IF(B15=0,VLOOKUP(A15,Feuil2!$A$2:$M$1241,11,FALSE)," ") | H15: C | I15: =IF(B15=0,VLOOKUP(A15,Feuil2!$A$2:$M$1241,7,FALSE)," ") | J15: =IF(B15=0,VLOOKUP(A15,Feuil2!$A$2:$M$1241,9,FALSE)," ") | K15: =IF(B15=0,VLOOKUP(A15,Feuil2!$A$2:$M$1241,10,FALSE)," ") | O15: =IF(B15=0,VLOOKUP(A15,Feuil2!$A$2:$M$1241,13,FALSE)," ")
A16: 225 | B16: 0 | C16: =IF(B16=0,VLOOKUP(A16,Feuil2!$A$2:$M$1241,2,FALSE)," ") -> LAYOUNI | D16: =IF(B16=0,VLOOKUP(A16,Feuil2!$A$2:$M$1241,3,FALSE)," ") -> ABDELKARIM | E16: =IF(B16=0,VLOOKUP(A16,Feuil2!$A$2:$M$1241,6,FALSE)," ") -> 24122 | F16: =IF(B16=0,VLOOKUP(A16,Feuil2!$A$2:$M$1241,12,FALSE)," ") -> H | G16: =IF(B16=0,VLOOKUP(A16,Feuil2!$A$2:$M$1241,11,FALSE)," ") -> M | H16: C | I16: =IF(B16=0,VLOOKUP(A16,Feuil2!$A$2:$M$1241,7,FALSE)," ") -> 2966905 | J16: =IF(B16=0,VLOOKUP(A16,Feuil2!$A$2:$M$1241,9,FALSE)," ") -> 86 R 1er juin 1955 | K16: =IF(B16=0,VLOOKUP(A16,Feuil2!$A$2:$M$1241,10,FALSE)," ") -> Msaken 4070 | L16: 4070 | M16: 98793641 | O16: =IF(B16=0,VLOOKUP(A16,Feuil2!$A$2:$M$1241,13,FALSE)," ") -> 12505000000214557279
A17: 225 | B17: 1 | C17: FATHALLAH | D17: BASMA | E17: 25586 | F17: F | G17: M | H17: C | I17: =IF(B17=0,VLOOKUP(A17,Feuil2!$A$2:$M$1241,7,FALSE)," ") | J17: =IF(B17=0,VLOOKUP(A17,Feuil2!$A$2:$M$1241,9,FALSE)," ") | K17: =IF(B17=0,VLOOKUP(A17,Feuil2!$A$2:$M$1241,10,FALSE)," ") | O17: =IF(B17=0,VLOOKUP(A17,Feuil2!$A$2:$M$1241,13,FALSE)," ")
A18: 225 | B18: 2 | C18: LAYOUNI | D18: MARIEM | E18: 34440 | F18: F | G18: =IF(B18=0,VLOOKUP(A18,Feuil2!$A$2:$M$1241,11,FALSE)," ") | H18: C | I18: =IF(B18=0,VLOOKUP(A18,Feuil2!$A$2:$M$1241,7,FALSE)," ") | J18: =IF(B18=0,VLOOKUP(A18,Feuil2!$A$2:$M$1241,9,FALSE)," ") | K18: =IF(B18=0,VLOOKUP(A18,Feuil2!$A$2:$M$1241,10,FALSE)," ") | O18: =IF(B18=0,VLOOKUP(A18,Feuil2!$A$2:$M$1241,13,FALSE)," ")
A19: 225 | B19: 3 | C19: LAYOUNI | D19: ZAINEB | E19: 36496 | F19: F | G19: =IF(B19=0,VLOOKUP(A19,Feuil2!$A$2:$M$1241,11,FALSE)," ") | H19: C | I19: =IF(B19=0,VLOOKUP(A19,Feuil2!$A$2:$M$1241,7,FALSE)," ") | J19: =IF(B19=0,VLOOKUP(A19,Feuil2!$A$2:$M$1241,9,FALSE)," ") | K19: =IF(B19=0,VLOOKUP(A19,Feuil2!$A$2:$M$1241,10,FALSE)," ") | O19: =IF(B19=0,VLOOKUP(A19,Feuil2!$A$2:$M$1241,13,FALSE)," ")
A20: 280 | B20: 0 | C20: =IF(B20=0,VLOOKUP(A20,Feuil2!$A$2:$M$1241,2,FALSE)," ") -> LAYOUNI | D20: =IF(B20=0,VLOOKUP(A20,Feuil2!$A$2:$M$1241,3,FALSE)," ") -> GHAZI | E20: =IF(B20=0,VLOOKUP(A20,Feuil2!$A$2:$M$1241,6,FALSE)," ") -> 24181 | F20: =IF(B20=0,VLOOKUP(A20,Feuil2!$A$2:$M$1241,12,FALSE)," ") -> H | G20: =IF(B20=0,VLOOKUP(A20,Feuil2!$A$2:$M$1241,11,FALSE)," ") -> M | H20: C | I20: =IF(B20=0,VLOOKUP(A20,Feuil2!$A$2:$M$1241,7,FALSE)," ") -> 3370974 | J20: =IF(B20=0,VLOOKUP(A20,Feuil2!$A$2:$M$1241,9,FALSE)," ") -> Rue 1er juin 1955 | K20: =IF(B20=0,VLOOKUP(A20,Feuil2!$A$2:$M$1241,10,FALSE)," ") -> Msaken 4070 | L20: 4070 | M20: 98257075 | O20: =IF(B20=0,VLOOKUP(A20,Feuil2!$A$2:$M$1241,13,FALSE)," ") -> 20009090001145941227
A21: 280 | B21: 1 | C21: BEN TAKIA | D21: MANAL | E21: 29790 | F21: F | G21: M | H21: C | I21: =IF(B21=0,VLOOKUP(A21,Feuil2!$A$2:$M$1241,7,FALSE)," ") | J21: =IF(B21=0,VLOOKUP(A21,Feuil2!$A$2:$M$1241,9,FALSE)," ") | K21: =IF(B21=0,VLOOKUP(A21,Feuil2!$A$2:$M$1241,10,FALSE)," ") | O21: =IF(B21=0,VLOOKUP(A21,Feuil2!$A$2:$M$1241,13,FALSE)," ") | P21: PARTANT
A22: 280 | B22: 2 | C22: LAYOUNI | D22: SOFIENE | E22: 39776 | F22: H | G22: =IF(B22=0,VLOOKUP(A22,Feuil2!$A$2:$M$1241,11,FALSE)," ") | H22: C | I22: =IF(B22=0,VLOOKUP(A22,Feuil2!$A$2:$M$1241,7,FALSE)," ") | J22: =IF(B22=0,VLOOKUP(A22,Feuil2!$A$2:$M$1241,9,FALSE)," ") | K22: =IF(B22=0,VLOOKUP(A22,Feuil2!$A$2:$M$1241,10,FALSE)," ") | O22: =IF(B22=0,VLOOKUP(A22,Feuil2!$A$2:$M$1241,13,FALSE)," ")
A23: 280 | B23: 3 | C23: LAYOUNI | D23: MAYSSA | E23: 41199 | F23: F | G23: =IF(B23=0,VLOOKUP(A23,Feuil2!$A$2:$M$1241,11,FALSE)," ") | H23: C | I23: =IF(B23=0,VLOOKUP(A23,Feuil2!$A$2:$M$1241,7,FALSE)," ") | J23: =IF(B23=0,VLOOKUP(A23,Feuil2!$A$2:$M$1241,9,FALSE)," ") | K23: =IF(B23=0,VLOOKUP(A23,Feuil2!$A$2:$M$1241,10,FALSE)," ") | O23: =IF(B23=0,VLOOKUP(A23,Feuil2!$A$2:$M$1241,13,FALSE)," ")
A24: 344 | B24: 0 | C24: =IF(B24=0,VLOOKUP(A24,Feuil2!$A$2:$M$1241,2,FALSE)," ") -> TERZAG EL BHIRI | D24: =IF(B24=0,VLOOKUP(A24,Feuil2!$A$2:$M$1241,3,FALSE)," ") -> CHEDLY | E24: =IF(B24=0,VLOOKUP(A24,Feuil2!$A$2:$M$1241,6,FALSE)," ") -> 23694 | F24: =IF(B24=0,VLOOKUP(A24,Feuil2!$A$2:$M$1241,12,FALSE)," ") -> H | G24: =IF(B24=0,VLOOKUP(A24,Feuil2!$A$2:$M$1241,11,FALSE)," ") -> M | H24: C | I24: =IF(B24=0,VLOOKUP(A24,Feuil2!$A$2:$M$1241,7,FALSE)," ") -> 2952362 | J24: =IF(B24=0,VLOOKUP(A24,Feuil2!$A$2:$M$1241,9,FALSE)," ") -> 68 Rue Essomaa | K24: =IF(B24=0,VLOOKUP(A24,Feuil2!$A$2:$M$1241,10,FALSE)," ") -> Msaken 4070 | L24: 4070 | M24: 98793754 | O24: 12505000582700754647
A25: 344 | B25: 1 | C25: BHIRI | D25: AMEL | E25: 27213 | F25: F | G25: M | H25: C | I25: =IF(B25=0,VLOOKUP(A25,Feuil2!$A$2:$M$1241,7,FALSE)," ") | J25: =IF(B25=0,VLOOKUP(A25,Feuil2!$A$2:$M$1241,9,FALSE)," ") | K25: =IF(B25=0,VLOOKUP(A25,Feuil2!$A$2:$M$1241,10,FALSE)," ") | O25: =IF(B25=0,VLOOKUP(A25,Feuil2!$A$2:$M$1241,13,FALSE)," ")
A26: 344 | B26: 2 | C26: TERZAG EL BHIRI | D26: YASSINE | E26: 36333 | F26: H | G26: =IF(B26=0,VLOOKUP(A26,Feuil2!$A$2:$M$1241,11,FALSE)," ") | H26: C | I26: =IF(B26=0,VLOOKUP(A26,Feuil2!$A$2:$M$1241,7,FALSE)," ") | J26: =IF(B26=0,VLOOKUP(A26,Feuil2!$A$2:$M$1241,9,FALSE)," ") | K26: =IF(B26=0,VLOOKUP(A26,Feuil2!$A$2:$M$1241,10,FALSE)," ") | O26: =IF(B26=0,VLOOKUP(A26,Feuil2!$A$2:$M$1241,13,FALSE)," ")
A27: 344 | B27: 3 | C27: TERZAG EL BHIRI | D27: FREDJ | E27: 42349 | F27: H | G27: =IF(B27=0,VLOOKUP(A27,Feuil2!$A$2:$M$1241,11,FALSE)," ") | H27: C | I27: =IF(B27=0,VLOOKUP(A27,Feuil2!$A$2:$M$1241,7,FALSE)," ") | J27: =IF(B27=0,VLOOKUP(A27,Feuil2!$A$2:$M$1241,9,FALSE)," ") | K27: =IF(B27=0,VLOOKUP(A27,Feuil2!$A$2:$M$1241,10,FALSE)," ") | O27: =IF(B27=0,VLOOKUP(A27,Feuil2!$A$2:$M$1241,13,FALSE)," ")
A28: 368 | B28: 0 | C28: =IF(B28=0,VLOOKUP(A28,Feuil2!$A$2:$M$1241,2,FALSE)," ") -> AJROUD | D28: =IF(B28=0,VLOOKUP(A28,Feuil2!$A$2:$M$1241,3,FALSE)," ") -> RIDHA | E28: =IF(B28=0,VLOOKUP(A28,Feuil2!$A$2:$M$1241,6,FALSE)," ") -> 23531 | F28: =IF(B28=0,VLOOKUP(A28,Feuil2!$A$2:$M$1241,12,FALSE)," ") -> H | G28: =IF(B28=0,VLOOKUP(A28,Feuil2!$A$2:$M$1241,11,FALSE)," ") -> M | H28: C | I28: =IF(B28=0,VLOOKUP(A28,Feuil2!$A$2:$M$1241,7,FALSE)," ") -> 2952022 | J28: =IF(B28=0,VLOOKUP(A28,Feuil2!$A$2:$M$1241,9,FALSE)," ") -> 53 Rue de Bizert | K28: =IF(B28=0,VLOOKUP(A28,Feuil2!$A$2:$M$1241,10,FALSE)," ") -> Msaken 4070 | L28: 4070 | M28: 96327094 | O28: =IF(B28=0,VLOOKUP(A28,Feuil2!$A$2:$M$1241,13,FALSE)," ") -> 10506040203075578841
A29: 368 | B29: 1 | C29: BEN SALEM | D29: SONIA | E29: 28084 | F29: F | G29: M | H29: C | I29: =IF(B29=0,VLOOKUP(A29,Feuil2!$A$2:$M$1241,7,FALSE)," ") | J29: =IF(B29=0,VLOOKUP(A29,Feuil2!$A$2:$M$1241,9,FALSE)," ") | K29: =IF(B29=0,VLOOKUP(A29,Feuil2!$A$2:$M$1241,10,FALSE)," ") | O29: =IF(B29=0,VLOOKUP(A29,Feuil2!$A$2:$M$1241,13,FALSE)," ")
A30: 368 | B30: 2 | C30: AJROUD | D30: RIHAM | E30: 35694 | F30: F | G30: =IF(B30=0,VLOOKUP(A30,Feuil2!$A$2:$M$1241,11,FALSE)," ") | H30: C | I30: =IF(B30=0,VLOOKUP(A30,Feuil2!$A$2:$M$1241,7,FALSE)," ") | J30: =IF(B30=0,VLOOKUP(A30,Feuil2!$A$2:$M$1241,9,FALSE)," ") | K30: =IF(B30=0,VLOOKUP(A30,Feuil2!$A$2:$M$1241,10,FALSE)," ") | O30: =IF(B30=0,VLOOKUP(A30,Feuil2!$A$2:$M$1241,13,FALSE)," ")
A31: 368 | B31: 3 | C31: AJROUD | D31: AHMED | E31: 37819 | F31: H | G31: =IF(B31=0,VLOOKUP(A31,Feuil2!$A$2:$M$1241,11,FALSE)," ") | H31: C | I31: =IF(B31=0,VLOOKUP(A31,Feuil2!$A$2:$M$1241,7,FALSE)," ") | J31: =IF(B31=0,VLOOKUP(A31,Feuil2!$A$2:$M$1241,9,FALSE)," ") | K31: =IF(B31=0,VLOOKUP(A31,Feuil2!$A$2:$M$1241,10,FALSE)," ") | O31: =IF(B31=0,VLOOKUP(A31,Feuil2!$A$2:$M$1241,13,FALSE)," ")
A32: 368 | B32: 4 | C32: AJROUD | D32: SALMA | E32: 40271 | F32: F | G32: =IF(B32=0,VLOOKUP(A32,Feuil2!$A$2:$M$1241,11,FALSE)," ") | H32: C | I32: =IF(B32=0,VLOOKUP(A32,Feuil2!$A$2:$M$1241,7,FALSE)," ") | J32: =IF(B32=0,VLOOKUP(A32,Feuil2!$A$2:$M$1241,9,FALSE)," ") | K32: =IF(B32=0,VLOOKUP(A32,Feuil2!$A$2:$M$1241,10,FALSE)," ") | O32: =IF(B32=0,VLOOKUP(A32,Feuil2!$A$2:$M$1241,13,FALSE)," ")
A33: 369 | B33: 0 | C33: =IF(B33=0,VLOOKUP(A33,Feuil2!$A$2:$M$1241,2,FALSE)," ") -> KECHICHE | D33: =IF(B33=0,VLOOKUP(A33,Feuil2!$A$2:$M$1241,3,FALSE)," ") -> BECHIR | E33: =IF(B33=0,VLOOKUP(A33,Feuil2!$A$2:$M$1241,6,FALSE)," ") -> 23172 | F33: =IF(B33=0,VLOOKUP(A33,Feuil2!$A$2:$M$1241,12,FALSE)," ") -> H | G33: =IF(B33=0,VLOOKUP(A33,Feuil2!$A$2:$M$1241,11,FALSE)," ") -> M | H33: C | I33: =IF(B33=0,VLOOKUP(A33,Feuil2!$A$2:$M$1241,7,FALSE)," ") -> 2947387 | J33: =IF(B33=0,VLOOKUP(A33,Feuil2!$A$2:$M$1241,9,FALSE)," ") -> 233 Rue Habib Thameur | K33: =IF(B33=0,VLOOKUP(A33,Feuil2!$A$2:$M$1241,10,FALSE)," ") -> Msaken 4070 | L33: 4070 | M33: 95236558 | O33: =IF(B33=0,VLOOKUP(A33,Feuil2!$A$2:$M$1241,13,FALSE)," ") -> 03508056010100091895
A34: 369 | B34: 1 | C34: MOSBAH | D34: SAMIA | E34: 25610 | F34: F | G34: M | H34: C | I34: =IF(B34=0,VLOOKUP(A34,Feuil2!$A$2:$M$1241,7,FALSE)," ") | J34: =IF(B34=0,VLOOKUP(A34,Feuil2!$A$2:$M$1241,9,FALSE)," ") | K34: =IF(B34=0,VLOOKUP(A34,Feuil2!$A$2:$M$1241,10,FALSE)," ") | O34: =IF(B34=0,VLOOKUP(A34,Feuil2!$A$2:$M$1241,13,FALSE)," ")
A35: 369 | B35: 2 | C35: KECHICHE | D35: SAIF | E35: 34933 | F35: H | G35: =IF(B35=0,VLOOKUP(A35,Feuil2!$A$2:$M$1241,11,FALSE)," ") | H35: C | I35: =IF(B35=0,VLOOKUP(A35,Feuil2!$A$2:$M$1241,7,FALSE)," ") | J35: =IF(B35=0,VLOOKUP(A35,Feuil2!$A$2:$M$1241,9,FALSE)," ") | K35: =IF(B35=0,VLOOKUP(A35,Feuil2!$A$2:$M$1241,10,FALSE)," ") | O35: =IF(B35=0,VLOOKUP(A35,Feuil2!$A$2:$M$1241,13,FALSE)," ")
A36: 369 | B36: 3 | C36: KECHICHE | D36: FATEN | E36: 35301 | F36: F | G36: =IF(B36=0,VLOOKUP(A36,Feuil2!$A$2:$M$1241,11,FALSE)," ") | H36: C | I36: =IF(B36=0,VLOOKUP(A36,Feuil2!$A$2:$M$1241,7,FALSE)," ") | J36: =IF(B36=0,VLOOKUP(A36,Feuil2!$A$2:$M$1241,9,FALSE)," ") | K36: =IF(B36=0,VLOOKUP(A36,Feuil2!$A$2:$M$1241,10,FALSE)," ") | O36: =IF(B36=0,VLOOKUP(A36,Feuil2!$A$2:$M$1241,13,FALSE)," ")
A37: 369 | B37: 4 | C37: KECHICHE | D37: SONIA | E37: 38491 | F37: F | G37: =IF(B37=0,VLOOKUP(A37,Feuil2!$A$2:$M$1241,11,FALSE)," ") | H37: C | I37: =IF(B37=0,VLOOKUP(A37,Feuil2!$A$2:$M$1241,7,FALSE)," ") | J37: =IF(B37=0,VLOOKUP(A37,Feuil2!$A$2:$M$1241,9,FALSE)," ") | K37: =IF(B37=0,VLOOKUP(A37,Feuil2!$A$2:$M$1241,10,FALSE)," ") | O37: =IF(B37=0,VLOOKUP(A37,Feuil2!$A$2:$M$1241,13,FALSE)," ")
A38: 369 | B38: 5 | C38: KECHICHE | D38: YOUSSEF | E38: 40383 | F38: H | G38: =IF(B38=0,VLOOKUP(A38,Feuil2!$A$2:$M$1241,11,FALSE)," ") | H38: C | I38: =IF(B38=0,VLOOKUP(A38,Feuil2!$A$2:$M$1241,7,FALSE)," ") | J38: =IF(B38=0,VLOOKUP(A38,Feuil2!$A$2:$M$1241,9,FALSE)," ") | K38: =IF(B38=0,VLOOKUP(A38,Feuil2!$A$2:$M$1241,10,FALSE)," ") | O38: =IF(B38=0,VLOOKUP(A38,Feuil2!$A$2:$M$1241,13,FALSE)," ")
A39: 382 | B39: 0 | C39: =IF(B39=0,VLOOKUP(A39,Feuil2!$A$2:$M$1241,2,FALSE)," ") -> HAMILA | D39: =IF(B39=0,VLOOKUP(A39,Feuil2!$A$2:$M$1241,3,FALSE)," ") -> KHALED | E39: =IF(B39=0,VLOOKUP(A39,Feuil2!$A$2:$M$1241,6,FALSE)," ") -> 23821 | F39: =IF(B39=0,VLOOKUP(A39,Feuil2!$A$2:$M$1241,12,FALSE)," ") -> H | G39: =IF(B39=0,VLOOKUP(A39,Feuil2!$A$2:$M$1241,11,FALSE)," ") -> M | H39: C | I39: =IF(B39=0,VLOOKUP(A39,Feuil2!$A$2:$M$1241,7,FALSE)," ") -> 2969788 | J39: =IF(B39=0,VLOOKUP(A39,Feuil2!$A$2:$M$1241,9,FALSE)," ") -> 18 bis Rue Bilel Ben Ribeh | K39: =IF(B39=0,VLOOKUP(A39,Feuil2!$A$2:$M$1241,10,FALSE)," ") -> Msaken 4070 | L39: 4070 | M39: 98547800 | O39: =IF(B39=0,VLOOKUP(A39,Feuil2!$A$2:$M$1241,13,FALSE)," ") -> 03508056010100157952
A40: 382 | B40: 1 | C40: GHOUL BHIRI | D40: SONIA | E40: 27809 | F40: F | G40: M | H40: C | I40: =IF(B40=0,VLOOKUP(A40,Feuil2!$A$2:$M$1241,7,FALSE)," ") | J40: =IF(B40=0,VLOOKUP(A40,Feuil2!$A$2:$M$1241,9,FALSE)," ") | K40: =IF(B40=0,VLOOKUP(A40,Feuil2!$A$2:$M$1241,10,FALSE)," ") | O40: =IF(B40=0,VLOOKUP(A40,Feuil2!$A$2:$M$1241,13,FALSE)," ")
...

Sheet Feuil2
A1: 1 | B1: 2 | C1: 3 | D1: 4 | E1: 5 | F1: 6 | G1: 7 | H1: 8 | I1: 9 | J1: 10 | K1: 11 | L1: 12 | M1: 13
A2: Mle | B2: Nom | C2: Prenom | D2: Nom Père | E2: Nom mere | F2: Date naissance | G2: CIN | H2: CNSS | I2: Adresse | K2: S.F | L2: Sexe
A3: 9 | B3: BEL HEDI | C3: SALOUA | D3: NULL | E3: NULL | F3: NULL | G3: NULL | H3: NULL | I3: NULL | J3: NULL | K3: M | L3: NULL | M3: =VLOOKUP(A3,[1]MSAKEN!$A$1:$F$562,6,FALSE) -> #N/A
A4: 10 | B4: GHALI | C4: NEJIB | D4: NULL | E4: NULL | F4: 19244 | G4: 4027920 | H4: 1103813505 | I4: 112 Avenu Habib Bourguiba | J4: Teboulba | K4: M | L4: H | M4: =VLOOKUP(A4,[1]MSAKEN!$A$1:$F$562,6,FALSE) -> #N/A
A5: 13 | B5: EL OUAFI | C5: KAMEL | D5: NULL | E5: NULL | F5: NULL | G5: NULL | H5: NULL | I5: NULL | J5: NULL | K5: M | L5: NULL | M5: =VLOOKUP(A5,[1]MSAKEN!$A$1:$F$562,6,FALSE) -> #N/A
A6: 14 | B6: GHRAIEB | C6: SALEM | D6: NULL | E6: NULL | F6: NULL | G6: 22756 | H6: 0 | I6: NULL | J6: NULL | K6: M | L6: H | M6: =VLOOKUP(A6,[1]MSAKEN!$A$1:$F$562,6,FALSE) -> #N/A
A7: 15 | B7: ERNEZ | C7: ZOUHAIER | D7: NULL | E7: NULL | F7: 18803 | G7: 2956086 | H7: 1109266500 | I7: Rue El Houlel Essoundoussia Khezama Ouest | J7: Sousse | K7: M | L7: H | M7: =VLOOKUP(A7,[1]MSAKEN!$A$1:$F$562,6,FALSE) -> #N/A
A8: 16 | B8: LACHHAB | C8: HEDI | D8: NULL | E8: NULL | F8: 19595 | G8: 2930962 | H8: 1106329400 | I8: Rue de Khourtoum | J8: Msaken 4070 | K8: M | L8: H | M8: =VLOOKUP(A8,[1]MSAKEN!$A$1:$F$562,6,FALSE) -> #N/A
A9: 19 | B9: BOUCHAHDA | C9: MOHAMED LAMINE | D9: NULL | E9: NULL | F9: NULL | G9: NULL | H9: NULL | I9: NULL | J9: NULL | K9: NULL | L9: NULL | M9: =VLOOKUP(A9,[1]MSAKEN!$A$1:$F$562,6,FALSE) -> #N/A
A10: 21 | B10: REGAIEG | C10: MOHAMED TAIEB | D10: NULL | E10: NULL | F10: NULL | G10: 2858128 | H10: 91623900 | I10: 54 Rue du Martyr Ahmed Regaieg | J10: NULL | K10: M | L10: H | M10: =VLOOKUP(A10,[1]MSAKEN!$A$1:$F$562,6,FALSE) -> #N/A
A11: 22 | B11: HAMILA | C11: FAYCAL | D11: NULL | E11: NULL | F11: 20202 | G11: 2841277 | H11: 1109281905 | I11: 4, Rue Ahmed Chaouki | J11: Msaken 4070 | K11: M | L11: H | M11: =VLOOKUP(A11,[1]MSAKEN!$A$1:$F$562,6,FALSE) -> #N/A
A12: 23 | B12: RAZGALLAH | C12: MOHAMED HABIB | D12: Mahmoud | E12: Cherifa | F12: 20640 | G12: 2832555 | H12: 88722500 | I12: 6 Rue de la Garre | J12: Msaken 4070 | K12: M | L12: H | M12: =VLOOKUP(A12,[1]MSAKEN!$A$1:$F$562,6,FALSE) -> #N/A
A13: 24 | B13: DABBABI | C13: AFIFA | D13: NULL | E13: NULL | F13: 21089 | G13: 2892540 | H13: 88087300 | I13: Rue abdelaziz El Aroui Skanes | J13: Monastir | K13: M | L13: F | M13: =VLOOKUP(A13,[1]MSAKEN!$A$1:$F$562,6,FALSE) -> #N/A
A14: 27 | B14: HARIRA | C14: HEDI | D14: NULL | E14: NULL | F14: NULL | G14: 1907895 | H14: 85868600 | I14: P T T De Cherarda kairouan | J14: NULL | K14: M | L14: H | M14: =VLOOKUP(A14,[1]MSAKEN!$A$1:$F$562,6,FALSE) -> #N/A
A15: 30 | B15: TRAD | C15: AMOR | D15: NULL | E15: NULL | F15: NULL | G15: 351112 | H15: 1113506206 | I15: Rue de Koweit | J15: Msaken 4070 | K15: M | L15: H | M15: =VLOOKUP(A15,[1]MSAKEN!$A$1:$F$562,6,FALSE) -> #N/A
A16: 31 | B16: KOUADA | C16: ABDERRAHMEN | D16: NULL | E16: NULL | F16: 19698 | G16: 2859124 | H16: 865670 | I16: 26,Rue Ouifek | J16: Msaken 4070 | K16: M | L16: H | M16: =VLOOKUP(A16,[1]MSAKEN!$A$1:$F$562,6,FALSE) -> #N/A
A17: 32 | B17: BRAHAM | C17: BRAHIM | D17: NULL | E17: NULL | F17: 19588 | G17: 1896154 | H17: 90058600 | I17: 517 Rue 1er Juin | J17: Msaken 4070 | K17: M | L17: H | M17: =VLOOKUP(A17,[1]MSAKEN!$A$1:$F$562,6,FALSE) -> #N/A
A18: 36 | B18: BAYA | C18: ADEL | D18: Mohamed | E18: Aicha | F18: 23421 | G18: 2867586 | H18: 1113546400 | I18: 467 Rue 1er juin | J18: Msaken 4070 | K18: M | L18: H | M18: =VLOOKUP(A18,[1]MSAKEN!$A$1:$F$562,6,FALSE) -> 24010030679251100000
A19: 37 | B19: BOUGI | C19: SLAH | D19: Hassine | E19: Aicha | F19: 21793 | G19: 2862435 | H19: 1113540809 | I19: 32 Rue Mongi Bali | J19: Msaken 4070 | K19: M | L19: H | M19: =VLOOKUP(A19,[1]MSAKEN!$A$1:$F$562,6,FALSE) -> #N/A
A20: 38 | B20: CHATTI | C20: RIDHA | D20: Mohamed | E20: Aicha | F20: 21959 | G20: 2835379 | H20: 1113540700 | I20: 59 R Chikh Sadok Chatti | J20: Msaken 4070 | K20: M | L20: H | M20: =VLOOKUP(A20,[1]MSAKEN!$A$1:$F$562,6,FALSE) -> #N/A
A21: 39 | B21: GUEZGUEZ | C21: MUSTAHPA FAOUZI | D21: Mohamed | E21: Chadlya | F21: 21295 | G21: 2831826 | H21: 1101321600 | I21: 01 Rue Fess | J21: Msaken 4070 | K21: M | L21: H | M21: =VLOOKUP(A21,[1]MSAKEN!$A$1:$F$562,6,FALSE) -> #N/A
A22: 40 | B22: MAJDOUB | C22: HABIB | D22: Ibrahim | E22: Zohra | F22: 23012 | G22: 2814018 | H22: 1113546509 | I22: CitÃ© Ennour rue Marrakech | J22: Msaken 4070 | K22: M | L22: H | M22: =VLOOKUP(A22,[1]MSAKEN!$A$1:$F$562,6,FALSE) -> 08507000262002303810
A23: 42 | B23: SGHAIER | C23: TAHAR | D23: NULL | E23: NULL | F23: 17603 | G23: 358006 | H23: 1109575720 | I23: 28 Rue de Bizerte | J23: Msaken 4070 | K23: M | L23: H | M23: =VLOOKUP(A23,[1]MSAKEN!$A$1:$F$562,6,FALSE) -> #N/A
A24: 45 | B24: LANDOULSI | C24: ABDELMEJID | D24: NULL | E24: NULL | F24: 17843 | G24: 2952752 | H24: 1103944805 | I24: Route de Kairouan | J24: Msaken 4070 | K24: M | L24: H | M24: =VLOOKUP(A24,[1]MSAKEN!$A$1:$F$562,6,FALSE) -> #N/A
A25: 46 | B25: LAYOUNI | C25: ALI | D25: NULL | E25: NULL | F25: NULL | G25: 2830821 | H25: 0 | I25: 86 Rue1er juin | J25: Msaken 4070 | K25: M | L25: H | M25: =VLOOKUP(A25,[1]MSAKEN!$A$1:$F$562,6,FALSE) -> #N/A
A26: 48 | B26: GHACHEM | C26: MOHAMED RIDHA | D26: NULL | E26: NULL | F26: NULL | G26: 2834620 | H26: 0 | I26: NULL | J26: NULL | K26: M | L26: H | M26: =VLOOKUP(A26,[1]MSAKEN!$A$1:$F$562,6,FALSE) -> #N/A
A27: 50 | B27: JEDIDI | C27: DALENDA | D27: NULL | E27: NULL | F27: NULL | G27: NULL | H27: NULL | I27: NULL | J27: NULL | K27: M | L27: NULL | M27: =VLOOKUP(A27,[1]MSAKEN!$A$1:$F$562,6,FALSE) -> #N/A
A28: 52 | B28: FRIGUI | C28: MOHAMED | D28: NULL | E28: NULL | F28: 18669 | G28: 2841373 | H28: 92883300 | I28: Sousse | J28: Sousse | K28: M | L28: H | M28: =VLOOKUP(A28,[1]MSAKEN!$A$1:$F$562,6,FALSE) -> #N/A
A29: 53 | B29: BEN HMIDA | C29: MOUNIR | D29: NULL | E29: NULL | F29: NULL | G29: 2955164 | H29: 1104977002 | I29: 4 Rue Salah Hafsa | J29: Msaken 4070 | K29: M | L29: H | M29: =VLOOKUP(A29,[1]MSAKEN!$A$1:$F$562,6,FALSE) -> #N/A
A30: 55 | B30: GAMHA | C30: RACHIDA | D30: NULL | E30: NULL | F30: 19861 | G30: 2923773 | H30: 1114954306 | I30: 63 Rue 20 Mars | J30: Msaken 4070 | K30: M | L30: F | M30: =VLOOKUP(A30,[1]MSAKEN!$A$1:$F$562,6,FALSE) -> #N/A
A31: 56 | B31: KAIBI | C31: HEDI | D31: NULL | E31: NULL | F31: 17345 | G31: 2961712 | H31: 1112067507 | I31: 64 Rue de la mosquÃ© | J31: Msaken 4070 | K31: M | L31: H | M31: =VLOOKUP(A31,[1]MSAKEN!$A$1:$F$562,6,FALSE) -> #N/A
A32: 57 | B32: ZAGGAR | C32: MOHAMED | D32: NULL | E32: NULL | F32: 18910 | G32: 2819185 | H32: 77858700 | I32: 37 Rue martyr Salah Hafsa | J32: Msaken 4070 | K32: M | L32: H | M32: =VLOOKUP(A32,[1]MSAKEN!$A$1:$F$562,6,FALSE) -> #N/A
A33: 58 | B33: BEN HAMOUDA | C33: MONDHER | D33: Ali | E33: Cherifa | F33: 22824 | G33: 2933895 | H33: 1113528408 | I33: 158 Rue Imam El Mezri | J33: Msaken 4070 | K33: M | L33: H | M33: =VLOOKUP(A33,[1]MSAKEN!$A$1:$F$562,6,FALSE) -> 08507000262000767912
A34: 59 | B34: BEN MOHAMED | C34: BRAHIM | D34: NULL | E34: NULL | F34: NULL | G34: 353410 | H34: 1106173709 | I34: 4014 Knaies | J34: Knaies 4014 | K34: M | L34: H | M34: =VLOOKUP(A34,[1]MSAKEN!$A$1:$F$562,6,FALSE) -> #N/A
A35: 60 | B35: BOUHLEL | C35: LOTFI | D35: Mohamed | E35: Emna | F35: 21398 | G35: 2851619 | H35: 1112625502 | I35: 12 Rue des Oranges | J35: Msaken 4070 | K35: M | L35: H | M35: =VLOOKUP(A35,[1]MSAKEN!$A$1:$F$562,6,FALSE) -> #N/A
A36: 61 | B36: EL GARES | C36: MOHAMED | D36: NULL | E36: NULL | F36: 22767 | G36: 2943660 | H36: 1111565402 | I36: Rue naceur Bay R de la Cornich | J36: Sousse | K36: M | L36: H | M36: =VLOOKUP(A36,[1]MSAKEN!$A$1:$F$562,6,FALSE) -> #N/A
A37: 63 | B37: M'KHININI | C37: RIDHA | D37: NULL | E37: NULL | F37: 20848 | G37: 2840417 | H37: 1111324701 | I37: Rue Mustapha Kheraief | J37: Messadine 4013 | K37: M | L37: H | M37: =VLOOKUP(A37,[1]MSAKEN!$A$1:$F$562,6,FALSE) -> #N/A
A38: 67 | B38: DOURA | C38: KHEDIJA | D38: NULL | E38: NULL | F38: NULL | G38: 2873223 | H38: 77540100 | I38: Rue BÃ©chir Maarouf Bouraoui | J38: NULL | K38: V | L38: F | M38: =VLOOKUP(A38,[1]MSAKEN!$A$1:$F$562,6,FALSE) -> #N/A
A39: 68 | B39: KECHICHE | C39: BOURAOUI | D39: NULL | E39: NULL | F39: NULL | G39: 2963314 | H39: 1111599302 | I39: 225 R Habib Thameur | J39: Msaken 4070 | K39: M | L39: H | M39: =VLOOKUP(A39,[1]MSAKEN!$A$1:$F$562,6,FALSE) -> #N/A
A40: 70 | B40: ROMDHANE | C40: MOHAMED ABDDENNACEUR | D40: NULL | E40: NULL | F40: 20070 | G40: 2971134 | H40: 1112277601 | I40: 53 Rue Ahmed Regaieg | J40: Msaken 4070 | K40: M | L40: H | M40: =VLOOKUP(A40,[1]MSAKEN!$A$1:$F$562,6,FALSE) -> #N/A
...

Sheet Feuil3
A1: S/D RH-RP USINE DE MSAKEN
C2: ASSURANCE GROUPE
A3: CHANGEMENT DES BENEFICIAIRES EN CAS
C4: DE DECES
A6: MLE | C6: NOM | D6: PRENOM | E6: OBSERVATION
A7: 36 | B7: 0 | C7: =IF(B7=0,VLOOKUP(A7,Feuil2!$A$2:$M$1241,2,FALSE)," ") -> BAYA | D7: =IF(B7=0,VLOOKUP(A7,Feuil2!$A$2:$M$1241,3,FALSE)," ") -> ADEL | E7: OK
A8: 58 | B8: 0 | C8: =IF(B8=0,VLOOKUP(A8,Feuil2!$A$2:$M$1241,2,FALSE)," ") -> BEN HAMOUDA | D8: =IF(B8=0,VLOOKUP(A8,Feuil2!$A$2:$M$1241,3,FALSE)," ") -> MONDHER | E8: OK
A9: 100 | B9: 0 | C9: =IF(B9=0,VLOOKUP(A9,Feuil2!$A$2:$M$1241,2,FALSE)," ") -> JARRAR | D9: =IF(B9=0,VLOOKUP(A9,Feuil2!$A$2:$M$1241,3,FALSE)," ") -> JALEL BEN ALI | E9: OK
A10: 144 | B10: 0 | C10: =IF(B10=0,VLOOKUP(A10,Feuil2!$A$2:$M$1241,2,FALSE)," ") -> DHIFALLAH | D10: =IF(B10=0,VLOOKUP(A10,Feuil2!$A$2:$M$1241,3,FALSE)," ") -> MOHAMED | E10: OK
A11: 145 | B11: 0 | C11: =IF(B11=0,VLOOKUP(A11,Feuil2!$A$2:$M$1241,2,FALSE)," ") -> GAZZAH | D11: =IF(B11=0,VLOOKUP(A11,Feuil2!$A$2:$M$1241,3,FALSE)," ") -> MAHMOUD | E11: OK
A12: 166 | B12: 0 | C12: =IF(B12=0,VLOOKUP(A12,Feuil2!$A$2:$M$1241,2,FALSE)," ") -> GRASSA | D12: =IF(B12=0,VLOOKUP(A12,Feuil2!$A$2:$M$1241,3,FALSE)," ") -> ABDELHAMID | E12: OK
A13: 212 | B13: 0 | C13: =IF(B13=0,VLOOKUP(A13,Feuil2!$A$2:$M$1241,2,FALSE)," ") -> BOUHLEL | D13: =IF(B13=0,VLOOKUP(A13,Feuil2!$A$2:$M$1241,3,FALSE)," ") -> BECHIR | E13: OK
A14: 369 | B14: 0 | C14: =IF(B14=0,VLOOKUP(A14,Feuil2!$A$2:$M$1241,2,FALSE)," ") -> KECHICHE | D14: =IF(B14=0,VLOOKUP(A14,Feuil2!$A$2:$M$1241,3,FALSE)," ") -> BECHIR | E14: OK
A15: 480 | B15: 0 | C15: =IF(B15=0,VLOOKUP(A15,Feuil2!$A$2:$M$1241,2,FALSE)," ") -> TOUMI | D15: =IF(B15=0,VLOOKUP(A15,Feuil2!$A$2:$M$1241,3,FALSE)," ") -> CHOKRI | E15: OK
A16: 482 | B16: 0 | C16: =IF(B16=0,VLOOKUP(A16,Feuil2!$A$2:$M$1241,2,FALSE)," ") -> MAATOUG | D16: =IF(B16=0,VLOOKUP(A16,Feuil2!$A$2:$M$1241,3,FALSE)," ") -> HMAIED | E16: OK
A17: 497 | B17: 0 | C17: =IF(B17=0,VLOOKUP(A17,Feuil2!$A$2:$M$1241,2,FALSE)," ") -> BEN ABDALLAH | D17: =IF(B17=0,VLOOKUP(A17,Feuil2!$A$2:$M$1241,3,FALSE)," ") -> TAOUFIK | E17: OK
A18: 498 | B18: 0 | C18: =IF(B18=0,VLOOKUP(A18,Feuil2!$A$2:$M$1241,2,FALSE)," ") -> DHIB | D18: =IF(B18=0,VLOOKUP(A18,Feuil2!$A$2:$M$1241,3,FALSE)," ") -> TAOUFIK | E18: OK
... A234: 1829 | B234: 0 | C234: =IF(B234=0,VLOOKUP(A234,Feuil2!$A$2:$M$1241,2,FALSE)," ") -> ATROUS | D234: =IF(B234=0,VLOOKUP(A234,Feuil2!$A$2:$M$1241,3,FALSE)," ") -> ANIS | E234: OK
A235: 1830 | B235: 0 | C235: =IF(B235=0,VLOOKUP(A235,Feuil2!$A$2:$M$1241,2,FALSE)," ") -> LOURIMI | D235: ABDALLAH | E235: OK
A236: 1831 | B236: 0 | C236: =IF(B236=0,VLOOKUP(A236,Feuil2!$A$2:$M$1241,2,FALSE)," ") -> KEMIMECH | D236: =IF(B236=0,VLOOKUP(A236,Feuil2!$A$2:$M$1241,3,FALSE)," ") -> MOHAMED BEN MOHAMED | E236: OK
A237: 1832 | B237: 0 | C237: =IF(B237=0,VLOOKUP(A237,Feuil2!$A$2:$M$1241,2,FALSE)," ") -> ERGUEZ | D237: =IF(B237=0,VLOOKUP(A237,Feuil2!$A$2:$M$1241,3,FALSE)," ") -> MEJDI | E237: OK
A238: 1833 | B238: 0 | C238: =IF(B238=0,VLOOKUP(A238,Feuil2!$A$2:$M$1241,2,FALSE)," ") -> BOUZAABIA | D238: =IF(B238=0,VLOOKUP(A238,Feuil2!$A$2:$M$1241,3,FALSE)," ") -> MOHAMED | E238: OK
A239: 1834 | B239: 0 | C239: =IF(B239=0,VLOOKUP(A239,Feuil2!$A$2:$M$1241,2,FALSE)," ") -> SMIDA | D239: =IF(B239=0,VLOOKUP(A239,Feuil2!$A$2:$M$1241,3,FALSE)," ") -> ZIED | E239: OK
A240: 1835 | B240: 0 | C240: =IF(B240=0,VLOOKUP(A240,Feuil2!$A$2:$M$1241,2,FALSE)," ") -> KRIFA | D240: =IF(B240=0,VLOOKUP(A240,Feuil2!$A$2:$M$1241,3,FALSE)," ") -> MOHAMED KAMEL | E240: OK
A241: 1836 | B241: 0 | C241: =IF(B241=0,VLOOKUP(A241,Feuil2!$A$2:$M$1241,2,FALSE)," ") -> BEN KALIA | D241: =IF(B241=0,VLOOKUP(A241,Feuil2!$A$2:$M$1241,3,FALSE)," ") -> LOTFI | E241: OK
A242: 1837 | B242: 0 | C242: =IF(B242=0,VLOOKUP(A242,Feuil2!$A$2:$M$1241,2,FALSE)," ") -> SLAMA | D242: =IF(B242=0,VLOOKUP(A242,Feuil2!$A$2:$M$1241,3,FALSE)," ") -> SALEM | E242: OK
A243: 1839 | B243: 0 | C243: =IF(B243=0,VLOOKUP(A243,Feuil2!$A$2:$M$1241,2,FALSE)," ") -> TERZEGUE | D243: =IF(B243=0,VLOOKUP(A243,Feuil2!$A$2:$M$1241,3,FALSE)," ") -> FERID | E243: OK
A244: 1842 | B244: 0 | C244: =IF(B244=0,VLOOKUP(A244,Feuil2!$A$2:$M$1241,2,FALSE)," ") -> SAKKA ROUIS | D244: =IF(B244=0,VLOOKUP(A244,Feuil2!$A$2:$M$1241,3,FALSE)," ") -> SAMI | E244: OK
A245: 1846 | B245: 0 | C245: =IF(B245=0,VLOOKUP(A245,Feuil2!$A$2:$M$1241,2,FALSE)," ") -> ROMDHANI | D245: =IF(B245=0,VLOOKUP(A245,Feuil2!$A$2:$M$1241,3,FALSE)," ") -> SAMI | E245: OK
A246: 1849 | B246: 0 | C246: =IF(B246=0,VLOOKUP(A246,Feuil2!$A$2:$M$1241,2,FALSE)," ") -> GANHOUBA | D246: =IF(B246=0,VLOOKUP(A246,Feuil2!$A$2:$M$1241,3,FALSE)," ") -> MEHDI | E246: OK
A247: 1851 | B247: 0 | C247: =IF(B247=0,VLOOKUP(A247,Feuil2!$A$2:$M$1241,2,FALSE)," ") -> ATTIA | D247: =IF(B247=0,VLOOKUP(A247,Feuil2!$A$2:$M$1241,3,FALSE)," ") -> FAYCAL | E247: OK
... A277: 1914 | B277: 0 | C277: =IF(B277=0,VLOOKUP(A277,Feuil2!$A$2:$M$1241,2,FALSE)," ") -> EL FKIH | D277: =IF(B277=0,VLOOKUP(A277,Feuil2!$A$2:$M$1241,3,FALSE)," ") -> LAMJED | E277: OK
A278: 1915 | B278: 0 | C278: BEN ABDALLAH | D278: =IF(B278=0,VLOOKUP(A278,Feuil2!$A$2:$M$1241,3,FALSE)," ") -> MOHAMED SALAH | E278: OK
A279: 1916 | B279: 0 | C279: =IF(B279=0,VLOOKUP(A279,Feuil2!$A$2:$M$1241,2,FALSE)," ") -> MANSOUR | D279: =IF(B279=0,VLOOKUP(A279,Feuil2!$A$2:$M$1241,3,FALSE)," ") -> NEJI | E279: OK
A280: 1917 | B280: 0 | C280: =IF(B280=0,VLOOKUP(A280,Feuil2!$A$2:$M$1241,2,FALSE)," ") -> HAMILA | D280: =IF(B280=0,VLOOKUP(A280,Feuil2!$A$2:$M$1241,3,FALSE)," ") -> JAMEL | E280: OK
A281: 1918 | B281: 0 | C281: =IF(B281=0,VLOOKUP(A281,Feuil2!$A$2:$M$1241,2,FALSE)," ") -> BOURIGUA | D281: =IF(B281=0,VLOOKUP(A281,Feuil2!$A$2:$M$1241,3,FALSE)," ") -> MOHAMED ALI | E281: OK
A282: 1919 | B282: 0 | C282: =IF(B282=0,VLOOKUP(A282,Feuil2!$A$2:$M$1241,2,FALSE)," ") -> SOUA LAYOUNI | D282: =IF(B282=0,VLOOKUP(A282,Feuil2!$A$2:$M$1241,3,FALSE)," ") -> MOHAMED | E282: OK
A283: 1921 | B283: 0 | C283: =IF(B283=0,VLOOKUP(A283,Feuil2!$A$2:$M$1241,2,FALSE)," ") -> HNIA | D283: =IF(B283=0,VLOOKUP(A283,Feuil2!$A$2:$M$1241,3,FALSE)," ") -> SAHNOUN | E283: OK
A284: 1922 | B284: 0 | C284: =IF(B284=0,VLOOKUP(A284,Feuil2!$A$2:$M$1241,2,FALSE)," ") -> MAHJOUB | D284: =IF(B284=0,VLOOKUP(A284,Feuil2!$A$2:$M$1241,3,FALSE)," ") -> FAKER | E284: OK
A285: 1923 | B285: 0 | C285: =IF(B285=0,VLOOKUP(A285,Feuil2!$A$2:$M$1241,2,FALSE)," ") -> BOUAZZA | D285: =IF(B285=0,VLOOKUP(A285,Feuil2!$A$2:$M$1241,3,FALSE)," ") -> WALID | E285: OK
...

Sheet Feuil4
A1: matricule | B1: ordre | C1: nom | D1: prenom | E1: date_nais | F1: sexe | G1: etat_civil | H1: type_piece | I1: num_piece | J1: adresse | K1: ville | L1: code_postal | M1: gsm | N1: email | O1: rib
A2: 100 | B2: 0 | C2: =IF(B2=0,VLOOKUP(A2,Feuil2!$A$2:$M$1241,2,FALSE)," ") -> JARRAR | D2: =IF(B2=0,VLOOKUP(A2,Feuil2!$A$2:$M$1241,3,FALSE)," ") -> JALEL BEN ALI | E2: =IF(B2=0,VLOOKUP(A2,Feuil2!$A$2:$M$1241,6,FALSE)," ") -> 23125 | F2: =IF(B2=0,VLOOKUP(A2,Feuil2!$A$2:$M$1241,12,FALSE)," ") -> H | G2: =IF(B2=0,VLOOKUP(A2,Feuil2!$A$2:$M$1241,11,FALSE)," ") -> M | H2: C | I2: =IF(B2=0,VLOOKUP(A2,Feuil2!$A$2:$M$1241,7,FALSE)," ") -> 2961061 | J2: =IF(B2=0,VLOOKUP(A2,Feuil2!$A$2:$M$1241,9,FALSE)," ") -> 55 Route de Sfax | K2: =IF(B2=0,VLOOKUP(A2,Feuil2!$A$2:$M$1241,10,FALSE)," ") -> Msaken 4070 | L2: 4070 | M2: 98793700 | O2: =IF(B2=0,VLOOKUP(A2,Feuil2!$A$2:$M$1241,13,FALSE)," ") -> 11020002050700878842
A3: 100 | B3: 1 | C3: MLAYEH | D3: THOURAYA | E3: 26310 | F3: F | G3: M | H3: C | I3: =IF(B3=0,VLOOKUP(A3,Feuil2!$A$2:$M$1241,7,FALSE)," ") | J3: =IF(B3=0,VLOOKUP(A3,Feuil2!$A$2:$M$1241,9,FALSE)," ") | K3: =IF(B3=0,VLOOKUP(A3,Feuil2!$A$2:$M$1241,10,FALSE)," ") | O3: =IF(B3=0,VLOOKUP(A3,Feuil2!$A$2:$M$1241,13,FALSE)," ")
A4: 100 | B4: 2 | C4: JARRAR | D4: FOUED | E4: 35702 | F4: H | G4: =IF(B4=0,VLOOKUP(A4,Feuil2!$A$2:$M$1241,11,FALSE)," ") | H4: C | I4: =IF(B4=0,VLOOKUP(A4,Feuil2!$A$2:$M$1241,7,FALSE)," ") | J4: =IF(B4=0,VLOOKUP(A4,Feuil2!$A$2:$M$1241,9,FALSE)," ") | K4: =IF(B4=0,VLOOKUP(A4,Feuil2!$A$2:$M$1241,10,FALSE)," ") | O4: =IF(B4=0,VLOOKUP(A4,Feuil2!$A$2:$M$1241,13,FALSE)," ")
A5: 100 | B5: 3 | C5: JARRAR | D5: FATEN | E5: 36388 | F5: F | G5: =IF(B5=0,VLOOKUP(A5,Feuil2!$A$2:$M$1241,11,FALSE)," ") | H5: C | I5: =IF(B5=0,VLOOKUP(A5,Feuil2!$A$2:$M$1241,7,FALSE)," ") | J5: =IF(B5=0,VLOOKUP(A5,Feuil2!$A$2:$M$1241,9,FALSE)," ") | K5: =IF(B5=0,VLOOKUP(A5,Feuil2!$A$2:$M$1241,10,FALSE)," ") | O5: =IF(B5=0,VLOOKUP(A5,Feuil2!$A$2:$M$1241,13,FALSE)," ")
A6: 100 | B6: 4 | C6: JARRAR | D6: IBRAHIM | E6: 38394 | F6: H | G6: =IF(B6=0,VLOOKUP(A6,Feuil2!$A$2:$M$1241,11,FALSE)," ") | H6: C | I6: =IF(B6=0,VLOOKUP(A6,Feuil2!$A$2:$M$1241,7,FALSE)," ") | J6: =IF(B6=0,VLOOKUP(A6,Feuil2!$A$2:$M$1241,9,FALSE)," ") | K6: =IF(B6=0,VLOOKUP(A6,Feuil2!$A$2:$M$1241,10,FALSE)," ") | O6: =IF(B6=0,VLOOKUP(A6,Feuil2!$A$2:$M$1241,13,FALSE)," ")
A7: 100 | B7: 5 | C7: JARRAR | D7: SOUFIEN | E7: 38909 | F7: H | G7: =IF(B7=0,VLOOKUP(A7,Feuil2!$A$2:$M$1241,11,FALSE)," ") | H7: C | I7: =IF(B7=0,VLOOKUP(A7,Feuil2!$A$2:$M$1241,7,FALSE)," ") | J7: =IF(B7=0,VLOOKUP(A7,Feuil2!$A$2:$M$1241,9,FALSE)," ") | K7: =IF(B7=0,VLOOKUP(A7,Feuil2!$A$2:$M$1241,10,FALSE)," ") | O7: =IF(B7=0,VLOOKUP(A7,Feuil2!$A$2:$M$1241,13,FALSE)," ")
A8: 134 | B8: 1 | C8: JARRAR | D8: ZIED | E8: 34599 | F8: H | G8: =IF(B8=0,VLOOKUP(A8,Feuil2!$A$2:$M$1241,11,FALSE)," ") | H8: C | I8: =IF(B8=0,VLOOKUP(A8,Feuil2!$A$2:$M$1241,7,FALSE)," ") | J8: =IF(B8=0,VLOOKUP(A8,Feuil2!$A$2:$M$1241,9,FALSE)," ") | K8: =IF(B8=0,VLOOKUP(A8,Feuil2!$A$2:$M$1241,10,FALSE)," ")
A9: 185 | B9: 0 | C9: =IF(B9=0,VLOOKUP(A9,Feuil2!$A$2:$M$1241,2,FALSE)," ") -> MAHJOUB NOUIR | D9: =IF(B9=0,VLOOKUP(A9,Feuil2!$A$2:$M$1241,3,FALSE)," ") -> MONCEF | E9: =IF(B9=0,VLOOKUP(A9,Feuil2!$A$2:$M$1241,6,FALSE)," ") -> 23612 | F9: =IF(B9=0,VLOOKUP(A9,Feuil2!$A$2:$M$1241,12,FALSE)," ") -> H | G9: =IF(B9=0,VLOOKUP(A9,Feuil2!$A$2:$M$1241,11,FALSE)," ") -> M | H9: C | I9: =IF(B9=0,VLOOKUP(A9,Feuil2!$A$2:$M$1241,7,FALSE)," ") -> 2959720 | J9: =IF(B9=0,VLOOKUP(A9,Feuil2!$A$2:$M$1241,9,FALSE)," ") -> 37 rue Ibn Rochd | K9: =IF(B9=0,VLOOKUP(A9,Feuil2!$A$2:$M$1241,10,FALSE)," ") -> Msaken 4070 | L9: 4070 | M9: 26836854 | O9: =IF(B9=0,VLOOKUP(A9,Feuil2!$A$2:$M$1241,13,FALSE)," ") -> 03508056010100247580
A10: 185 | B10: 1 | C10: ABBASS | D10: RADHIA | E10: 26829 | F10: F | G10: M | H10: C | I10: =IF(B10=0,VLOOKUP(A10,Feuil2!$A$2:$M$1241,7,FALSE)," ") | J10: =IF(B10=0,VLOOKUP(A10,Feuil2!$A$2:$M$1241,9,FALSE)," ") | K10: =IF(B10=0,VLOOKUP(A10,Feuil2!$A$2:$M$1241,10,FALSE)," ") | O10: =IF(B10=0,VLOOKUP(A10,Feuil2!$A$2:$M$1241,13,FALSE)," ")
A11: 185 | B11: 2 | C11: MAHJOUB NOUIR | D11: AYOUB | E11: 37775 | F11: H | G11: =IF(B11=0,VLOOKUP(A11,Feuil2!$A$2:$M$1241,11,FALSE)," ") | H11: C | I11: =IF(B11=0,VLOOKUP(A11,Feuil2!$A$2:$M$1241,7,FALSE)," ") | J11: =IF(B11=0,VLOOKUP(A11,Feuil2!$A$2:$M$1241,9,FALSE)," ") | K11: =IF(B11=0,VLOOKUP(A11,Feuil2!$A$2:$M$1241,10,FALSE)," ") | O11: =IF(B11=0,VLOOKUP(A11,Feuil2!$A$2:$M$1241,13,FALSE)," ")
A12: 212 | B12: 0 | C12: =IF(B12=0,VLOOKUP(A12,Feuil2!$A$2:$M$1241,2,FALSE)," ") -> BOUHLEL | D12: =IF(B12=0,VLOOKUP(A12,Feuil2!$A$2:$M$1241,3,FALSE)," ") -> BECHIR | E12: =IF(B12=0,VLOOKUP(A12,Feuil2!$A$2:$M$1241,6,FALSE)," ") -> 23594 | F12: =IF(B12=0,VLOOKUP(A12,Feuil2!$A$2:$M$1241,12,FALSE)," ") -> H | G12: =IF(B12=0,VLOOKUP(A12,Feuil2!$A$2:$M$1241,11,FALSE)," ") -> M | H12: C | I12: =IF(B12=0,VLOOKUP(A12,Feuil2!$A$2:$M$1241,7,FALSE)," ") -> 2954309 | J12: =IF(B12=0,VLOOKUP(A12,Feuil2!$A$2:$M$1241,9,FALSE)," ") -> Rue de Iran | K12: =IF(B12=0,VLOOKUP(A12,Feuil2!$A$2:$M$1241,10,FALSE)," ") -> Msaken 4070 | L12: 4070 | M12: 98793620 | O12: =IF(B12=0,VLOOKUP(A12,Feuil2!$A$2:$M$1241,13,FALSE)," ") -> 08507000262001609096
A13: 212 | B13: 1 | C13: GUEZGUEZ | D13: SAMIA | E13: 26636 | F13: F | G13: M | H13: C | I13: =IF(B13=0,VLOOKUP(A13,Feuil2!$A$2:$M$1241,7,FALSE)," ") | J13: =IF(B13=0,VLOOKUP(A13,Feuil2!$A$2:$M$1241,9,FALSE)," ") | K13: =IF(B13=0,VLOOKUP(A13,Feuil2!$A$2:$M$1241,10,FALSE)," ") | O13: =IF(B13=0,VLOOKUP(A13,Feuil2!$A$2:$M$1241,13,FALSE)," ")
A14: 212 | B14: 2 | C14: BOUHLEL | D14: YOUSSEF | E14: 40328 | F14: F | G14: =IF(B14=0,VLOOKUP(A14,Feuil2!$A$2:$M$1241,11,FALSE)," ") | H14: C | I14: =IF(B14=0,VLOOKUP(A14,Feuil2!$A$2:$M$1241,7,FALSE)," ") | J14: =IF(B14=0,VLOOKUP(A14,Feuil2!$A$2:$M$1241,9,FALSE)," ") | K14: =IF(B14=0,VLOOKUP(A14,Feuil2!$A$2:$M$1241,10,FALSE)," ") | O14: =IF(B14=0,VLOOKUP(A14,Feuil2!$A$2:$M$1241,13,FALSE)," ")
A15: 225 | B15: 0 | C15: =IF(B15=0,VLOOKUP(A15,Feuil2!$A$2:$M$1241,2,FALSE)," ") -> LAYOUNI | D15: =IF(B15=0,VLOOKUP(A15,Feuil2!$A$2:$M$1241,3,FALSE)," ") -> ABDELKARIM | E15: =IF(B15=0,VLOOKUP(A15,Feuil2!$A$2:$M$1241,6,FALSE)," ") -> 24122 | F15: =IF(B15=0,VLOOKUP(A15,Feuil2!$A$2:$M$1241,12,FALSE)," ") -> H | G15: =IF(B15=0,VLOOKUP(A15,Feuil2!$A$2:$M$1241,11,FALSE)," ") -> M | H15: C | I15: =IF(B15=0,VLOOKUP(A15,Feuil2!$A$2:$M$1241,7,FALSE)," ") -> 2966905 | J15: =IF(B15=0,VLOOKUP(A15,Feuil2!$A$2:$M$1241,9,FALSE)," ") -> 86 R 1er juin 1955 | K15: =IF(B15=0,VLOOKUP(A15,Feuil2!$A$2:$M$1241,10,FALSE)," ") -> Msaken 4070 | L15: 4070 | M15: 98793641 | O15: =IF(B15=0,VLOOKUP(A15,Feuil2!$A$2:$M$1241,13,FALSE)," ") -> 12505000000214557279
A16: 225 | B16: 1 | C16: FATHALLAH | D16: BASMA | E16: 25586 | F16: F | G16: M | H16: C | I16: =IF(B16=0,VLOOKUP(A16,Feuil2!$A$2:$M$1241,7,FALSE)," ") | J16: =IF(B16=0,VLOOKUP(A16,Feuil2!$A$2:$M$1241,9,FALSE)," ") | K16: =IF(B16=0,VLOOKUP(A16,Feuil2!$A$2:$M$1241,10,FALSE)," ") | O16: =IF(B16=0,VLOOKUP(A16,Feuil2!$A$2:$M$1241,13,FALSE)," ")
A17: 225 | B17: 2 | C17: LAYOUNI | D17: MARIEM | E17: 34440 | F17: F | G17: =IF(B17=0,VLOOKUP(A17,Feuil2!$A$2:$M$1241,11,FALSE)," ") | H17: C | I17: =IF(B17=0,VLOOKUP(A17,Feuil2!$A$2:$M$1241,7,FALSE)," ") | J17: =IF(B17=0,VLOOKUP(A17,Feuil2!$A$2:$M$1241,9,FALSE)," ") | K17: =IF(B17=0,VLOOKUP(A17,Feuil2!$A$2:$M$1241,10,FALSE)," ") | O17: =IF(B17=0,VLOOKUP(A17,Feuil2!$A$2:$M$1241,13,FALSE)," ")
A18: 225 | B18: 3 | C18: LAYOUNI | D18: ZAINEB | E18: 36496 | F18: F | G18: =IF(B18=0,VLOOKUP(A18,Feuil2!$A$2:$M$1241,11,FALSE)," ") | H18: C | I18: =IF(B18=0,VLOOKUP(A18,Feuil2!$A$2:$M$1241,7,FALSE)," ") | J18: =IF(B18=0,VLOOKUP(A18,Feuil2!$A$2:$M$1241,9,FALSE)," ") | K18: =IF(B18=0,VLOOKUP(A18,Feuil2!$A$2:$M$1241,10,FALSE)," ") | O18: =IF(B18=0,VLOOKUP(A18,Feuil2!$A$2:$M$1241,13,FALSE)," ")
A19: 280 | B19: 0 | C19: =IF(B19=0,VLOOKUP(A19,Feuil2!$A$2:$M$1241,2,FALSE)," ") -> LAYOUNI | D19: =IF(B19=0,VLOOKUP(A19,Feuil2!$A$2:$M$1241,3,FALSE)," ") -> GHAZI | E19: =IF(B19=0,VLOOKUP(A19,Feuil2!$A$2:$M$1241,6,FALSE)," ") -> 24181 | F19: =IF(B19=0,VLOOKUP(A19,Feuil2!$A$2:$M$1241,12,FALSE)," ") -> H | G19: =IF(B19=0,VLOOKUP(A19,Feuil2!$A$2:$M$1241,11,FALSE)," ") -> M | H19: C | I19: =IF(B19=0,VLOOKUP(A19,Feuil2!$A$2:$M$1241,7,FALSE)," ") -> 3370974 | J19: =IF(B19=0,VLOOKUP(A19,Feuil2!$A$2:$M$1241,9,FALSE)," ") -> Rue 1er juin 1955 | K19: =IF(B19=0,VLOOKUP(A19,Feuil2!$A$2:$M$1241,10,FALSE)," ") -> Msaken 4070 | L19: 4070 | M19: 98257075 | O19: =IF(B19=0,VLOOKUP(A19,Feuil2!$A$2:$M$1241,13,FALSE)," ") -> 20009090001145941227
A20: 280 | B20: 1 | C20: BEN TAKIA | D20: MANAL | E20: 29790 | F20: F | G20: M | H20: C | I20: =IF(B20=0,VLOOKUP(A20,Feuil2!$A$2:$M$1241,7,FALSE)," ") | J20: =IF(B20=0,VLOOKUP(A20,Feuil2!$A$2:$M$1241,9,FALSE)," ") | K20: =IF(B20=0,VLOOKUP(A20,Feuil2!$A$2:$M$1241,10,FALSE)," ") | O20: =IF(B20=0,VLOOKUP(A20,Feuil2!$A$2:$M$1241,13,FALSE)," ") | P20: PARTANT
A21: 280 | B21: 2 | C21: LAYOUNI | D21: SOFIENE | E21: 39776 | F21: H | G21: =IF(B21=0,VLOOKUP(A21,Feuil2!$A$2:$M$1241,11,FALSE)," ") | H21: C | I21: =IF(B21=0,VLOOKUP(A21,Feuil2!$A$2:$M$1241,7,FALSE)," ") | J21: =IF(B21=0,VLOOKUP(A21,Feuil2!$A$2:$M$1241,9,FALSE)," ") | K21: =IF(B21=0,VLOOKUP(A21,Feuil2!$A$2:$M$1241,10,FALSE)," ") | O21: =IF(B21=0,VLOOKUP(A21,Feuil2!$A$2:$M$1241,13,FALSE)," ")
A22: 280 | B22: 3 | C22: LAYOUNI | D22: MAYSSA | E22: 41199 | F22: F | G22: =IF(B22=0,VLOOKUP(A22,Feuil2!$A$2:$M$1241,11,FALSE)," ") | H22: C | I22: =IF(B22=0,VLOOKUP(A22,Feuil2!$A$2:$M$1241,7,FALSE)," ") | J22: =IF(B22=0,VLOOKUP(A22,Feuil2!$A$2:$M$1241,9,FALSE)," ") | K22: =IF(B22=0,VLOOKUP(A22,Feuil2!$A$2:$M$1241,10,FALSE)," ") | O22: =IF(B22=0,VLOOKUP(A22,Feuil2!$A$2:$M$1241,13,FALSE)," ")
A23: 344 | B23: 0 | C23: =IF(B23=0,VLOOKUP(A23,Feuil2!$A$2:$M$1241,2,FALSE)," ") -> TERZAG EL BHIRI | D23: =IF(B23=0,VLOOKUP(A23,Feuil2!$A$2:$M$1241,3,FALSE)," ") -> CHEDLY | E23: =IF(B23=0,VLOOKUP(A23,Feuil2!$A$2:$M$1241,6,FALSE)," ") -> 23694 | F23: =IF(B23=0,VLOOKUP(A23,Feuil2!$A$2:$M$1241,12,FALSE)," ") -> H | G23: =IF(B23=0,VLOOKUP(A23,Feuil2!$A$2:$M$1241,11,FALSE)," ") -> M | H23: C | I23: =IF(B23=0,VLOOKUP(A23,Feuil2!$A$2:$M$1241,7,FALSE)," ") -> 2952362 | J23: =IF(B23=0,VLOOKUP(A23,Feuil2!$A$2:$M$1241,9,FALSE)," ") -> 68 Rue Essomaa | K23: =IF(B23=0,VLOOKUP(A23,Feuil2!$A$2:$M$1241,10,FALSE)," ") -> Msaken 4070 | L23: 4070 | M23: 98793754 | O23: 12505000582700754647
A24: 344 | B24: 1 | C24: BHIRI | D24: AMEL | E24: 27213 | F24: F | G24: M | H24: C | I24: =IF(B24=0,VLOOKUP(A24,Feuil2!$A$2:$M$1241,7,FALSE)," ") | J24: =IF(B24=0,VLOOKUP(A24,Feuil2!$A$2:$M$1241,9,FALSE)," ") | K24: =IF(B24=0,VLOOKUP(A24,Feuil2!$A$2:$M$1241,10,FALSE)," ") | O24: =IF(B24=0,VLOOKUP(A24,Feuil2!$A$2:$M$1241,13,FALSE)," ")
A25: 344 | B25: 2 | C25: TERZAG EL BHIRI | D25: YASSINE | E25: 36333 | F25: H | G25: =IF(B25=0,VLOOKUP(A25,Feuil2!$A$2:$M$1241,11,FALSE)," ") | H25: C | I25: =IF(B25=0,VLOOKUP(A25,Feuil2!$A$2:$M$1241,7,FALSE)," ") | J25: =IF(B25=0,VLOOKUP(A25,Feuil2!$A$2:$M$1241,9,FALSE)," ") | K25: =IF(B25=0,VLOOKUP(A25,Feuil2!$A$2:$M$1241,10,FALSE)," ") | O25: =IF(B25=0,VLOOKUP(A25,Feuil2!$A$2:$M$1241,13,FALSE)," ")
A26: 344 | B26: 3 | C26: TERZAG EL BHIRI | D26: FREDJ | E26: 42349 | F26: H | G26: =IF(B26=0,VLOOKUP(A26,Feuil2!$A$2:$M$1241,11,FALSE)," ") | H26: C | I26: =IF(B26=0,VLOOKUP(A26,Feuil2!$A$2:$M$1241,7,FALSE)," ") | J26: =IF(B26=0,VLOOKUP(A26,Feuil2!$A$2:$M$1241,9,FALSE)," ") | K26: =IF(B26=0,VLOOKUP(A26,Feuil2!$A$2:$M$1241,10,FALSE)," ") | O26: =IF(B26=0,VLOOKUP(A26,Feuil2!$A$2:$M$1241,13,FALSE)," ")
A27: 368 | B27: 0 | C27: =IF(B27=0,VLOOKUP(A27,Feuil2!$A$2:$M$1241,2,FALSE)," ") -> AJROUD | D27: =IF(B27=0,VLOOKUP(A27,Feuil2!$A$2:$M$1241,3,FALSE)," ") -> RIDHA | E27: =IF(B27=0,VLOOKUP(A27,Feuil2!$A$2:$M$1241,6,FALSE)," ") -> 23531 | F27: =IF(B27=0,VLOOKUP(A27,Feuil2!$A$2:$M$1241,12,FALSE)," ") -> H | G27: =IF(B27=0,VLOOKUP(A27,Feuil2!$A$2:$M$1241,11,FALSE)," ") -> M | H27: C | I27: =IF(B27=0,VLOOKUP(A27,Feuil2!$A$2:$M$1241,7,FALSE)," ") -> 2952022 | J27: =IF(B27=0,VLOOKUP(A27,Feuil2!$A$2:$M$1241,9,FALSE)," ") -> 53 Rue de Bizert | K27: =IF(B27=0,VLOOKUP(A27,Feuil2!$A$2:$M$1241,10,FALSE)," ") -> Msaken 4070 | L27: 4070 | M27: 96327094 | O27: =IF(B27=0,VLOOKUP(A27,Feuil2!$A$2:$M$1241,13,FALSE)," ") -> 10506040203075578841
A28: 368 | B28: 1 | C28: BEN SALEM | D28: SONIA | E28: 28084 | F28: F | G28: M | H28: C | I28: =IF(B28=0,VLOOKUP(A28,Feuil2!$A$2:$M$1241,7,FALSE)," ") | J28: =IF(B28=0,VLOOKUP(A28,Feuil2!$A$2:$M$1241,9,FALSE)," ") | K28: =IF(B28=0,VLOOKUP(A28,Feuil2!$A$2:$M$1241,10,FALSE)," ") | O28: =IF(B28=0,VLOOKUP(A28,Feuil2!$A$2:$M$1241,13,FALSE)," ")
A29: 368 | B29: 2 | C29: AJROUD | D29: RIHAM | E29: 35694 | F29: F | G29: =IF(B29=0,VLOOKUP(A29,Feuil2!$A$2:$M$1241,11,FALSE)," ") | H29: C | I29: =IF(B29=0,VLOOKUP(A29,Feuil2!$A$2:$M$1241,7,FALSE)," ") | J29: =IF(B29=0,VLOOKUP(A29,Feuil2!$A$2:$M$1241,9,FALSE)," ") | K29: =IF(B29=0,VLOOKUP(A29,Feuil2!$A$2:$M$1241,10,FALSE)," ") | O29: =IF(B29=0,VLOOKUP(A29,Feuil2!$A$2:$M$1241,13,FALSE)," ")
A30: 368 | B30: 3 | C30: AJROUD | D30: AHMED | E30: 37819 | F30: H | G30: =IF(B30=0,VLOOKUP(A30,Feuil2!$A$2:$M$1241,11,FALSE)," ") | H30: C | I30: =IF(B30=0,VLOOKUP(A30,Feuil2!$A$2:$M$1241,7,FALSE)," ") | J30: =IF(B30=0,VLOOKUP(A30,Feuil2!$A$2:$M$1241,9,FALSE)," ") | K30: =IF(B30=0,VLOOKUP(A30,Feuil2!$A$2:$M$1241,10,FALSE)," ") | O30: =IF(B30=0,VLOOKUP(A30,Feuil2!$A$2:$M$1241,13,FALSE)," ")
A31: 368 | B31: 4 | C31: AJROUD | D31: SALMA | E31: 40271 | F31: F | G31: =IF(B31=0,VLOOKUP(A31,Feuil2!$A$2:$M$1241,11,FALSE)," ") | H31: C | I31: =IF(B31=0,VLOOKUP(A31,Feuil2!$A$2:$M$1241,7,FALSE)," ") | J31: =IF(B31=0,VLOOKUP(A31,Feuil2!$A$2:$M$1241,9,FALSE)," ") | K31: =IF(B31=0,VLOOKUP(A31,Feuil2!$A$2:$M$1241,10,FALSE)," ") | O31: =IF(B31=0,VLOOKUP(A31,Feuil2!$A$2:$M$1241,13,FALSE)," ")
A32: 369 | B32: 0 | C32: =IF(B32=0,VLOOKUP(A32,Feuil2!$A$2:$M$1241,2,FALSE)," ") -> KECHICHE | D32: =IF(B32=0,VLOOKUP(A32,Feuil2!$A$2:$M$1241,3,FALSE)," ") -> BECHIR | E32: =IF(B32=0,VLOOKUP(A32,Feuil2!$A$2:$M$1241,6,FALSE)," ") -> 23172 | F32: =IF(B32=0,VLOOKUP(A32,Feuil2!$A$2:$M$1241,12,FALSE)," ") -> H | G32: =IF(B32=0,VLOOKUP(A32,Feuil2!$A$2:$M$1241,11,FALSE)," ") -> M | H32: C | I32: =IF(B32=0,VLOOKUP(A32,Feuil2!$A$2:$M$1241,7,FALSE)," ") -> 2947387 | J32: =IF(B32=0,VLOOKUP(A32,Feuil2!$A$2:$M$1241,9,FALSE)," ") -> 233 Rue Habib Thameur | K32: =IF(B32=0,VLOOKUP(A32,Feuil2!$A$2:$M$1241,10,FALSE)," ") -> Msaken 4070 | L32: 4070 | M32: 95236558 | O32: =IF(B32=0,VLOOKUP(A32,Feuil2!$A$2:$M$1241,13,FALSE)," ") -> 03508056010100091895
A33: 369 | B33: 1 | C33: MOSBAH | D33: SAMIA | E33: 25610 | F33: F | G33: M | H33: C | I33: =IF(B33=0,VLOOKUP(A33,Feuil2!$A$2:$M$1241,7,FALSE)," ") | J33: =IF(B33=0,VLOOKUP(A33,Feuil2!$A$2:$M$1241,9,FALSE)," ") | K33: =IF(B33=0,VLOOKUP(A33,Feuil2!$A$2:$M$1241,10,FALSE)," ") | O33: =IF(B33=0,VLOOKUP(A33,Feuil2!$A$2:$M$1241,13,FALSE)," ")
A34: 369 | B34: 2 | C34: KECHICHE | D34: SAIF | E34: 34933 | F34: H | G34: =IF(B34=0,VLOOKUP(A34,Feuil2!$A$2:$M$1241,11,FALSE)," ") | H34: C | I34: =IF(B34=0,VLOOKUP(A34,Feuil2!$A$2:$M$1241,7,FALSE)," ") | J34: =IF(B34=0,VLOOKUP(A34,Feuil2!$A$2:$M$1241,9,FALSE)," ") | K34: =IF(B34=0,VLOOKUP(A34,Feuil2!$A$2:$M$1241,10,FALSE)," ") | O34: =IF(B34=0,VLOOKUP(A34,Feuil2!$A$2:$M$1241,13,FALSE)," ")
A35: 369 | B35: 3 | C35: KECHICHE | D35: FATEN | E35: 35301 | F35: F | G35: =IF(B35=0,VLOOKUP(A35,Feuil2!$A$2:$M$1241,11,FALSE)," ") | H35: C | I35: =IF(B35=0,VLOOKUP(A35,Feuil2!$A$2:$M$1241,7,FALSE)," ") | J35: =IF(B35=0,VLOOKUP(A35,Feuil2!$A$2:$M$1241,9,FALSE)," ") | K35: =IF(B35=0,VLOOKUP(A35,Feuil2!$A$2:$M$1241,10,FALSE)," ") | O35: =IF(B35=0,VLOOKUP(A35,Feuil2!$A$2:$M$1241,13,FALSE)," ")
A36: 369 | B36: 4 | C36: KECHICHE | D36: SONIA | E36: 38491 | F36: F | G36: =IF(B36=0,VLOOKUP(A36,Feuil2!$A$2:$M$1241,11,FALSE)," ") | H36: C | I36: =IF(B36=0,VLOOKUP(A36,Feuil2!$A$2:$M$1241,7,FALSE)," ") | J36: =IF(B36=0,VLOOKUP(A36,Feuil2!$A$2:$M$1241,9,FALSE)," ") | K36: =IF(B36=0,VLOOKUP(A36,Feuil2!$A$2:$M$1241,10,FALSE)," ") | O36: =IF(B36=0,VLOOKUP(A36,Feuil2!$A$2:$M$1241,13,FALSE)," ")
A37: 369 | B37: 5 | C37: KECHICHE | D37: YOUSSEF | E37: 40383 | F37: H | G37: =IF(B37=0,VLOOKUP(A37,Feuil2!$A$2:$M$1241,11,FALSE)," ") | H37: C | I37: =IF(B37=0,VLOOKUP(A37,Feuil2!$A$2:$M$1241,7,FALSE)," ") | J37: =IF(B37=0,VLOOKUP(A37,Feuil2!$A$2:$M$1241,9,FALSE)," ") | K37: =IF(B37=0,VLOOKUP(A37,Feuil2!$A$2:$M$1241,10,FALSE)," ") | O37: =IF(B37=0,VLOOKUP(A37,Feuil2!$A$2:$M$1241,13,FALSE)," ")
A38: 382 | B38: 0 | C38: =IF(B38=0,VLOOKUP(A38,Feuil2!$A$2:$M$1241,2,FALSE)," ") -> HAMILA | D38: =IF(B38=0,VLOOKUP(A38,Feuil2!$A$2:$M$1241,3,FALSE)," ") -> KHALED | E38: =IF(B38=0,VLOOKUP(A38,Feuil2!$A$2:$M$1241,6,FALSE)," ") -> 23821 | F38: =IF(B38=0,VLOOKUP(A38,Feuil2!$A$2:$M$1241,12,FALSE)," ") -> H | G38: =IF(B38=0,VLOOKUP(A38,Feuil2!$A$2:$M$1241,11,FALSE)," ") -> M | H38: C | I38: =IF(B38=0,VLOOKUP(A38,Feuil2!$A$2:$M$1241,7,FALSE)," ") -> 2969788 | J38: =IF(B38=0,VLOOKUP(A38,Feuil2!$A$2:$M$1241,9,FALSE)," ") -> 18 bis Rue Bilel Ben Ribeh | K38: =IF(B38=0,VLOOKUP(A38,Feuil2!$A$2:$M$1241,10,FALSE)," ") -> Msaken 4070 | L38: 4070 | M38: 98547800 | O38: =IF(B38=0,VLOOKUP(A38,Feuil2!$A$2:$M$1241,13,FALSE)," ") -> 03508056010100157952
A39: 382 | B39: 1 | C39: GHOUL BHIRI | D39: SONIA | E39: 27809 | F39: F | G39: M | H39: C | I39: =IF(B39=0,VLOOKUP(A39,Feuil2!$A$2:$M$1241,7,FALSE)," ") | J39: =IF(B39=0,VLOOKUP(A39,Feuil2!$A$2:$M$1241,9,FALSE)," ") | K39: =IF(B39=0,VLOOKUP(A39,Feuil2!$A$2:$M$1241,10,FALSE)," ") | O39: =IF(B39=0,VLOOKUP(A39,Feuil2!$A$2:$M$1241,13,FALSE)," ")
A40: 382 | B40: 2 | C40: HAMILA | D40: YOUSSEF | E40: 38330 | F40: H | G40: =IF(B40=0,VLOOKUP(A40,Feuil2!$A$2:$M$1241,11,FALSE)," ") | H40: C | I40: =IF(B40=0,VLOOKUP(A40,Feuil2!$A$2:$M$1241,7,FALSE)," ") | J40: =IF(B40=0,VLOOKUP(A40,Feuil2!$A$2:$M$1241,9,FALSE)," ") | K40: =IF(B40=0,VLOOKUP(A40,Feuil2!$A$2:$M$1241,10,FALSE)," ") | O40: =IF(B40=0,VLOOKUP(A40,Feuil2!$A$2:$M$1241,13,FALSE)," ")
...
